[2024-02-05T11:11:22.719+0000] {taskinstance.py:1956} INFO - Dependencies all met for dep_context=non-requeueable deps ti=<TaskInstance: Danalysis_json_processing_dag.load_data_task manual__2024-02-05T11:11:16.648530+00:00 [queued]>
[2024-02-05T11:11:22.776+0000] {taskinstance.py:1956} INFO - Dependencies all met for dep_context=requeueable deps ti=<TaskInstance: Danalysis_json_processing_dag.load_data_task manual__2024-02-05T11:11:16.648530+00:00 [queued]>
[2024-02-05T11:11:22.781+0000] {taskinstance.py:2170} INFO - Starting attempt 1 of 2
[2024-02-05T11:11:22.832+0000] {taskinstance.py:2191} INFO - Executing <Task(PythonOperator): load_data_task> on 2024-02-05 11:11:16.648530+00:00
[2024-02-05T11:11:22.851+0000] {standard_task_runner.py:60} INFO - Started process 896 to run task
[2024-02-05T11:11:22.867+0000] {standard_task_runner.py:87} INFO - Running: ['***', 'tasks', 'run', 'Danalysis_json_processing_dag', 'load_data_task', 'manual__2024-02-05T11:11:16.648530+00:00', '--job-id', '35', '--raw', '--subdir', 'DAGS_FOLDER/danalysis_dag.py', '--cfg-path', '/tmp/tmprmr84pzr']
[2024-02-05T11:11:22.873+0000] {standard_task_runner.py:88} INFO - Job 35: Subtask load_data_task
[2024-02-05T11:11:23.046+0000] {task_command.py:423} INFO - Running <TaskInstance: Danalysis_json_processing_dag.load_data_task manual__2024-02-05T11:11:16.648530+00:00 [running]> on host d3f529db5c6c
[2024-02-05T11:11:23.352+0000] {taskinstance.py:2480} INFO - Exporting env vars: AIRFLOW_CTX_DAG_OWNER='***' AIRFLOW_CTX_DAG_ID='Danalysis_json_processing_dag' AIRFLOW_CTX_TASK_ID='load_data_task' AIRFLOW_CTX_EXECUTION_DATE='2024-02-05T11:11:16.648530+00:00' AIRFLOW_CTX_TRY_NUMBER='1' AIRFLOW_CTX_DAG_RUN_ID='manual__2024-02-05T11:11:16.648530+00:00'
[2024-02-05T11:11:23.367+0000] {taskinstance.py:2698} ERROR - Task failed with exception
Traceback (most recent call last):
  File "/home/airflow/.local/lib/python3.8/site-packages/airflow/models/taskinstance.py", line 433, in _execute_task
    result = execute_callable(context=context, **execute_callable_kwargs)
  File "/home/airflow/.local/lib/python3.8/site-packages/airflow/operators/python.py", line 199, in execute
    return_value = self.execute_callable()
  File "/home/airflow/.local/lib/python3.8/site-packages/airflow/operators/python.py", line 216, in execute_callable
    return self.python_callable(*self.op_args, **self.op_kwargs)
  File "/opt/airflow/dags/danalysis_dag.py", line 22, in load_data
    with open(json_file_path, 'r') as json_file:
FileNotFoundError: [Errno 2] No such file or directory: '../jsonData/preferences.json'
[2024-02-05T11:11:23.408+0000] {taskinstance.py:1138} INFO - Marking task as UP_FOR_RETRY. dag_id=Danalysis_json_processing_dag, task_id=load_data_task, execution_date=20240205T111116, start_date=20240205T111122, end_date=20240205T111123
[2024-02-05T11:11:23.472+0000] {standard_task_runner.py:107} ERROR - Failed to execute job 35 for task load_data_task ([Errno 2] No such file or directory: '../jsonData/preferences.json'; 896)
[2024-02-05T11:11:23.576+0000] {local_task_job_runner.py:234} INFO - Task exited with return code 1
[2024-02-05T11:11:23.702+0000] {taskinstance.py:3280} INFO - 0 downstream tasks scheduled from follow-on schedule check
