[2024-02-05T21:24:45.823+0000] {taskinstance.py:1956} INFO - Dependencies all met for dep_context=non-requeueable deps ti=<TaskInstance: Danalysis_json_processing_dag.make_post_request_task manual__2024-02-05T21:24:24.247416+00:00 [queued]>
[2024-02-05T21:24:45.848+0000] {taskinstance.py:1956} INFO - Dependencies all met for dep_context=requeueable deps ti=<TaskInstance: Danalysis_json_processing_dag.make_post_request_task manual__2024-02-05T21:24:24.247416+00:00 [queued]>
[2024-02-05T21:24:45.863+0000] {taskinstance.py:2170} INFO - Starting attempt 1 of 2
[2024-02-05T21:24:45.923+0000] {taskinstance.py:2191} INFO - Executing <Task(PythonOperator): make_post_request_task> on 2024-02-05 21:24:24.247416+00:00
[2024-02-05T21:24:45.939+0000] {standard_task_runner.py:60} INFO - Started process 80 to run task
[2024-02-05T21:24:45.953+0000] {standard_task_runner.py:87} INFO - Running: ['***', 'tasks', 'run', 'Danalysis_json_processing_dag', 'make_post_request_task', 'manual__2024-02-05T21:24:24.247416+00:00', '--job-id', '94', '--raw', '--subdir', 'DAGS_FOLDER/danalysis_dag.py', '--cfg-path', '/tmp/tmp4s08ew6o']
[2024-02-05T21:24:45.959+0000] {standard_task_runner.py:88} INFO - Job 94: Subtask make_post_request_task
[2024-02-05T21:24:46.091+0000] {task_command.py:423} INFO - Running <TaskInstance: Danalysis_json_processing_dag.make_post_request_task manual__2024-02-05T21:24:24.247416+00:00 [running]> on host d3f529db5c6c
[2024-02-05T21:24:46.209+0000] {taskinstance.py:2480} INFO - Exporting env vars: AIRFLOW_CTX_DAG_EMAIL='amukayoung@gmail.com' AIRFLOW_CTX_DAG_OWNER='***' AIRFLOW_CTX_DAG_ID='Danalysis_json_processing_dag' AIRFLOW_CTX_TASK_ID='make_post_request_task' AIRFLOW_CTX_EXECUTION_DATE='2024-02-05T21:24:24.247416+00:00' AIRFLOW_CTX_TRY_NUMBER='1' AIRFLOW_CTX_DAG_RUN_ID='manual__2024-02-05T21:24:24.247416+00:00'
[2024-02-05T21:24:46.246+0000] {taskinstance.py:2698} ERROR - Task failed with exception
Traceback (most recent call last):
  File "/home/airflow/.local/lib/python3.8/site-packages/urllib3/connection.py", line 174, in _new_conn
    conn = connection.create_connection(
  File "/home/airflow/.local/lib/python3.8/site-packages/urllib3/util/connection.py", line 95, in create_connection
    raise err
  File "/home/airflow/.local/lib/python3.8/site-packages/urllib3/util/connection.py", line 85, in create_connection
    sock.connect(sa)
ConnectionRefusedError: [Errno 111] Connection refused

During handling of the above exception, another exception occurred:

Traceback (most recent call last):
  File "/home/airflow/.local/lib/python3.8/site-packages/urllib3/connectionpool.py", line 715, in urlopen
    httplib_response = self._make_request(
  File "/home/airflow/.local/lib/python3.8/site-packages/urllib3/connectionpool.py", line 416, in _make_request
    conn.request(method, url, **httplib_request_kw)
  File "/home/airflow/.local/lib/python3.8/site-packages/urllib3/connection.py", line 244, in request
    super(HTTPConnection, self).request(method, url, body=body, headers=headers)
  File "/usr/local/lib/python3.8/http/client.py", line 1256, in request
    self._send_request(method, url, body, headers, encode_chunked)
  File "/usr/local/lib/python3.8/http/client.py", line 1302, in _send_request
    self.endheaders(body, encode_chunked=encode_chunked)
  File "/usr/local/lib/python3.8/http/client.py", line 1251, in endheaders
    self._send_output(message_body, encode_chunked=encode_chunked)
  File "/usr/local/lib/python3.8/http/client.py", line 1011, in _send_output
    self.send(msg)
  File "/usr/local/lib/python3.8/http/client.py", line 951, in send
    self.connect()
  File "/home/airflow/.local/lib/python3.8/site-packages/urllib3/connection.py", line 205, in connect
    conn = self._new_conn()
  File "/home/airflow/.local/lib/python3.8/site-packages/urllib3/connection.py", line 186, in _new_conn
    raise NewConnectionError(
urllib3.exceptions.NewConnectionError: <urllib3.connection.HTTPConnection object at 0x7f63718f2340>: Failed to establish a new connection: [Errno 111] Connection refused

During handling of the above exception, another exception occurred:

Traceback (most recent call last):
  File "/home/airflow/.local/lib/python3.8/site-packages/requests/adapters.py", line 486, in send
    resp = conn.urlopen(
  File "/home/airflow/.local/lib/python3.8/site-packages/urllib3/connectionpool.py", line 799, in urlopen
    retries = retries.increment(
  File "/home/airflow/.local/lib/python3.8/site-packages/urllib3/util/retry.py", line 592, in increment
    raise MaxRetryError(_pool, url, error or ResponseError(cause))
urllib3.exceptions.MaxRetryError: HTTPConnectionPool(host='localhost', port=8000): Max retries exceeded with url: /device_***/ (Caused by NewConnectionError('<urllib3.connection.HTTPConnection object at 0x7f63718f2340>: Failed to establish a new connection: [Errno 111] Connection refused'))

During handling of the above exception, another exception occurred:

Traceback (most recent call last):
  File "/home/airflow/.local/lib/python3.8/site-packages/airflow/models/taskinstance.py", line 433, in _execute_task
    result = execute_callable(context=context, **execute_callable_kwargs)
  File "/home/airflow/.local/lib/python3.8/site-packages/airflow/operators/python.py", line 199, in execute
    return_value = self.execute_callable()
  File "/home/airflow/.local/lib/python3.8/site-packages/airflow/operators/python.py", line 216, in execute_callable
    return self.python_callable(*self.op_args, **self.op_kwargs)
  File "/opt/airflow/dags/danalysis_dag.py", line 72, in make_post_request
    response = requests.post(api_endpoint, json=item)
  File "/home/airflow/.local/lib/python3.8/site-packages/requests/api.py", line 115, in post
    return request("post", url, data=data, json=json, **kwargs)
  File "/home/airflow/.local/lib/python3.8/site-packages/requests/api.py", line 59, in request
    return session.request(method=method, url=url, **kwargs)
  File "/home/airflow/.local/lib/python3.8/site-packages/requests/sessions.py", line 589, in request
    resp = self.send(prep, **send_kwargs)
  File "/home/airflow/.local/lib/python3.8/site-packages/requests/sessions.py", line 703, in send
    r = adapter.send(request, **kwargs)
  File "/home/airflow/.local/lib/python3.8/site-packages/requests/adapters.py", line 519, in send
    raise ConnectionError(e, request=request)
requests.exceptions.ConnectionError: HTTPConnectionPool(host='localhost', port=8000): Max retries exceeded with url: /device_***/ (Caused by NewConnectionError('<urllib3.connection.HTTPConnection object at 0x7f63718f2340>: Failed to establish a new connection: [Errno 111] Connection refused'))
[2024-02-05T21:24:46.267+0000] {taskinstance.py:1138} INFO - Marking task as UP_FOR_RETRY. dag_id=Danalysis_json_processing_dag, task_id=make_post_request_task, execution_date=20240205T212424, start_date=20240205T212445, end_date=20240205T212446
[2024-02-05T21:24:46.290+0000] {standard_task_runner.py:107} ERROR - Failed to execute job 94 for task make_post_request_task (HTTPConnectionPool(host='localhost', port=8000): Max retries exceeded with url: /device_***/ (Caused by NewConnectionError('<urllib3.connection.HTTPConnection object at 0x7f63718f2340>: Failed to establish a new connection: [Errno 111] Connection refused')); 80)
[2024-02-05T21:24:46.338+0000] {local_task_job_runner.py:234} INFO - Task exited with return code 1
[2024-02-05T21:24:46.364+0000] {taskinstance.py:3280} INFO - 0 downstream tasks scheduled from follow-on schedule check
