[2024-02-05T11:01:54.528+0000] {taskinstance.py:1956} INFO - Dependencies all met for dep_context=non-requeueable deps ti=<TaskInstance: Danalysis_json_processing_dag.load_data_task manual__2024-02-05T10:55:27.853164+00:00 [queued]>
[2024-02-05T11:01:54.780+0000] {taskinstance.py:1956} INFO - Dependencies all met for dep_context=requeueable deps ti=<TaskInstance: Danalysis_json_processing_dag.load_data_task manual__2024-02-05T10:55:27.853164+00:00 [queued]>
[2024-02-05T11:01:54.784+0000] {taskinstance.py:2170} INFO - Starting attempt 2 of 2
[2024-02-05T11:01:54.939+0000] {taskinstance.py:2191} INFO - Executing <Task(PythonOperator): load_data_task> on 2024-02-05 10:55:27.853164+00:00
[2024-02-05T11:01:55.060+0000] {standard_task_runner.py:60} INFO - Started process 759 to run task
[2024-02-05T11:01:55.118+0000] {standard_task_runner.py:87} INFO - Running: ['***', 'tasks', 'run', 'Danalysis_json_processing_dag', 'load_data_task', 'manual__2024-02-05T10:55:27.853164+00:00', '--job-id', '31', '--raw', '--subdir', 'DAGS_FOLDER/danalysis_dag.py', '--cfg-path', '/tmp/tmpvoxwchbq']
[2024-02-05T11:01:55.160+0000] {standard_task_runner.py:88} INFO - Job 31: Subtask load_data_task
[2024-02-05T11:01:56.040+0000] {task_command.py:423} INFO - Running <TaskInstance: Danalysis_json_processing_dag.load_data_task manual__2024-02-05T10:55:27.853164+00:00 [running]> on host d3f529db5c6c
[2024-02-05T11:01:57.103+0000] {taskinstance.py:2480} INFO - Exporting env vars: AIRFLOW_CTX_DAG_OWNER='***' AIRFLOW_CTX_DAG_ID='Danalysis_json_processing_dag' AIRFLOW_CTX_TASK_ID='load_data_task' AIRFLOW_CTX_EXECUTION_DATE='2024-02-05T10:55:27.853164+00:00' AIRFLOW_CTX_TRY_NUMBER='2' AIRFLOW_CTX_DAG_RUN_ID='manual__2024-02-05T10:55:27.853164+00:00'
[2024-02-05T11:01:57.111+0000] {taskinstance.py:2698} ERROR - Task failed with exception
Traceback (most recent call last):
  File "/home/airflow/.local/lib/python3.8/site-packages/airflow/models/taskinstance.py", line 433, in _execute_task
    result = execute_callable(context=context, **execute_callable_kwargs)
  File "/home/airflow/.local/lib/python3.8/site-packages/airflow/operators/python.py", line 199, in execute
    return_value = self.execute_callable()
  File "/home/airflow/.local/lib/python3.8/site-packages/airflow/operators/python.py", line 216, in execute_callable
    return self.python_callable(*self.op_args, **self.op_kwargs)
  File "/opt/airflow/dags/danalysis_dag.py", line 22, in load_data
    with open(json_file_path, 'r') as json_file:
FileNotFoundError: [Errno 2] No such file or directory: './jsonData/preferences.json'
[2024-02-05T11:01:57.193+0000] {taskinstance.py:1138} INFO - Marking task as FAILED. dag_id=Danalysis_json_processing_dag, task_id=load_data_task, execution_date=20240205T105527, start_date=20240205T110154, end_date=20240205T110157
[2024-02-05T11:01:57.324+0000] {standard_task_runner.py:107} ERROR - Failed to execute job 31 for task load_data_task ([Errno 2] No such file or directory: './jsonData/preferences.json'; 759)
[2024-02-05T11:01:57.512+0000] {local_task_job_runner.py:234} INFO - Task exited with return code 1
[2024-02-05T11:01:58.112+0000] {taskinstance.py:3280} INFO - 0 downstream tasks scheduled from follow-on schedule check
