[2024-02-05T10:55:52.725+0000] {taskinstance.py:1956} INFO - Dependencies all met for dep_context=non-requeueable deps ti=<TaskInstance: Danalysis_json_processing_dag.load_data_task scheduled__2024-02-02T00:00:00+00:00 [queued]>
[2024-02-05T10:55:52.990+0000] {taskinstance.py:1956} INFO - Dependencies all met for dep_context=requeueable deps ti=<TaskInstance: Danalysis_json_processing_dag.load_data_task scheduled__2024-02-02T00:00:00+00:00 [queued]>
[2024-02-05T10:55:53.003+0000] {taskinstance.py:2170} INFO - Starting attempt 1 of 2
[2024-02-05T10:55:53.226+0000] {taskinstance.py:2191} INFO - Executing <Task(PythonOperator): load_data_task> on 2024-02-02 00:00:00+00:00
[2024-02-05T10:55:53.365+0000] {standard_task_runner.py:60} INFO - Started process 662 to run task
[2024-02-05T10:55:53.461+0000] {standard_task_runner.py:87} INFO - Running: ['***', 'tasks', 'run', 'Danalysis_json_processing_dag', 'load_data_task', 'scheduled__2024-02-02T00:00:00+00:00', '--job-id', '25', '--raw', '--subdir', 'DAGS_FOLDER/danalysis_dag.py', '--cfg-path', '/tmp/tmphpyzaovu']
[2024-02-05T10:55:53.522+0000] {standard_task_runner.py:88} INFO - Job 25: Subtask load_data_task
[2024-02-05T10:55:54.044+0000] {task_command.py:423} INFO - Running <TaskInstance: Danalysis_json_processing_dag.load_data_task scheduled__2024-02-02T00:00:00+00:00 [running]> on host d3f529db5c6c
[2024-02-05T10:55:55.216+0000] {taskinstance.py:2480} INFO - Exporting env vars: AIRFLOW_CTX_DAG_OWNER='***' AIRFLOW_CTX_DAG_ID='Danalysis_json_processing_dag' AIRFLOW_CTX_TASK_ID='load_data_task' AIRFLOW_CTX_EXECUTION_DATE='2024-02-02T00:00:00+00:00' AIRFLOW_CTX_TRY_NUMBER='1' AIRFLOW_CTX_DAG_RUN_ID='scheduled__2024-02-02T00:00:00+00:00'
[2024-02-05T10:55:55.237+0000] {taskinstance.py:2698} ERROR - Task failed with exception
Traceback (most recent call last):
  File "/home/airflow/.local/lib/python3.8/site-packages/airflow/models/taskinstance.py", line 433, in _execute_task
    result = execute_callable(context=context, **execute_callable_kwargs)
  File "/home/airflow/.local/lib/python3.8/site-packages/airflow/operators/python.py", line 199, in execute
    return_value = self.execute_callable()
  File "/home/airflow/.local/lib/python3.8/site-packages/airflow/operators/python.py", line 216, in execute_callable
    return self.python_callable(*self.op_args, **self.op_kwargs)
  File "/opt/airflow/dags/danalysis_dag.py", line 22, in load_data
    with open(json_file_path, 'r') as json_file:
FileNotFoundError: [Errno 2] No such file or directory: '../jsonData/preferences.json'
[2024-02-05T10:55:55.298+0000] {taskinstance.py:1138} INFO - Marking task as UP_FOR_RETRY. dag_id=Danalysis_json_processing_dag, task_id=load_data_task, execution_date=20240202T000000, start_date=20240205T105552, end_date=20240205T105555
[2024-02-05T10:55:55.440+0000] {standard_task_runner.py:107} ERROR - Failed to execute job 25 for task load_data_task ([Errno 2] No such file or directory: '../jsonData/preferences.json'; 662)
[2024-02-05T10:55:55.632+0000] {local_task_job_runner.py:234} INFO - Task exited with return code 1
[2024-02-05T10:55:56.226+0000] {taskinstance.py:3280} INFO - 0 downstream tasks scheduled from follow-on schedule check
