[2024-02-12T16:19:52.761+0000] {scheduler_job_runner.py:1586} WARNING - Marking task instance <TaskInstance: Danalysis_json_processing_dag.load_data_task scheduled__2024-02-10T00:00:00+00:00 [queued]> stuck in queued as failed. If the task instance has available retries, it will be retried.
[2024-02-12T16:19:54.925+0000] {scheduler_job_runner.py:781} ERROR - Executor reports task instance <TaskInstance: Danalysis_json_processing_dag.load_data_task scheduled__2024-02-10T00:00:00+00:00 [queued]> finished (failed) although the task says it's queued. (Info: None) Was the task killed externally?
